Workbook

Sheet Employee_Data
A1: Emp_ID | B1: Name | C1: Department | D1: Designation | E1: Date_of_Joining | F1: Age | G1: Gender | H1: City | I1: Monthly_Salary | J1: Performance_Rating | K1: Attendance_% | L1: Status | M1: Exit_Month | N1: Years_of_Experience | O1: Training_Completed
A2: EMP001 | B2: Amit Sharma | C2: Marketing | D2: Marketing Exec | E2: 09-12-2024 | F2: 23 | G2: Male | H2: Mumbai | I2: 30012 | J2: 3 | K2: 75.8 | L2: Resigned | M2: Feb-24 | N2: 1 | O2: No
A3: EMP002 | B3: Rahul Joshi | C3: IT | D3: Tech Lead | E3: 07-09-2024 | F3: 26 | G3: Female | H3: Bangalore | I3: 49731 | J3: 5 | K3: 83.3 | L3: Active | N3: 1 | O3: Yes
A4: EMP003 | B4: Amit Shah | C4: HR | D4: HR Executive | E4: 03-02-2019 | F4: 32 | G4: Male | H4: Hyderabad | I4: 31224 | J4: 3 | K4: 81.7 | L4: Active | N4: 6 | O4: Yes
A5: EMP004 | B5: Varun Patel | C5: Sales | D5: Sales Manager | E5: 20-11-2020 | F5: 29 | G5: Male | H5: Mumbai | I5: 42507 | J5: 4 | K5: 87.6 | L5: Active | N5: 5 | O5: Yes
A6: EMP005 | B6: Siddharth Kapoor | C6: Sales | D6: Sr Sales Exec | E6: 21-08-2020 | F6: 27 | G6: Male | H6: Pune | I6: 41666 | J6: 4 | K6: 76.4 | L6: Active | N6: 5 | O6: Yes
A7: EMP006 | B7: Aarti Agarwal | C7: HR | D7: Recruiter | E7: 06-04-2013 | F7: 34 | G7: Male | H7: Delhi | I7: 32573 | J7: 4 | K7: 79.3 | L7: Active | N7: 12 | O7: Yes
A8: EMP007 | B8: Tanvi Reddy | C8: Finance | D8: Sr Analyst | E8: 07-02-2020 | F8: 30 | G8: Male | H8: Bangalore | I8: 46960 | J8: 2 | K8: 95.7 | L8: Active | N8: 5 | O8: No
A9: EMP008 | B9: Sahil Mehta | C9: HR | D9: HR Executive | E9: 18-09-2013 | F9: 38 | G9: Female | H9: Delhi | I9: 29304 | J9: 2 | K9: 83.6 | L9: Active | N9: 12 | O9: Yes
A10: EMP009 | B10: Pallavi Yadav | C10: Sales | D10: Sales Exec | E10: 06-11-2022 | F10: 29 | G10: Male | H10: Pune | I10: 40977 | J10: 4 | K10: 88.1 | L10: Active | N10: 3 | O10: No
A11: EMP010 | B11: Rahul Yadav | C11: Marketing | D11: Marketing Exec | E11: 25-09-2014 | F11: 37 | G11: Male | H11: Chennai | I11: 30371 | J11: 4 | K11: 75 | L11: Active | N11: 11 | O11: No
A12: EMP011 | B12: Ravi Agarwal | C12: Sales | D12: Sales Manager | E12: 17-11-2020 | F12: 30 | G12: Male | H12: Delhi | I12: 37977 | J12: 3 | K12: 76.1 | L12: Active | N12: 5 | O12: Yes
A13: EMP012 | B13: Karan Mehta | C13: Finance | D13: Sr Analyst | E13: 08-01-2021 | F13: 27 | G13: Female | H13: Chennai | I13: 46385 | J13: 2 | K13: 97.6 | L13: Resigned | M13: Aug-24 | N13: 4 | O13: Yes
A14: EMP013 | B14: Tanvi Kapoor | C14: HR | D14: HR Manager | E14: 14-10-2016 | F14: 33 | G14: Female | H14: Chennai | I14: 28470 | J14: 5 | K14: 92.4 | L14: Active | N14: 9 | O14: Yes
A15: EMP014 | B15: Rahul Singh | C15: Operations | D15: Ops Executive | E15: 03-04-2021 | F15: 26 | G15: Male | H15: Delhi | I15: 32539 | J15: 2 | K15: 87.9 | L15: Active | N15: 4 | O15: Yes
A16: EMP015 | B16: Abhishek Iyer | C16: Sales | D16: Sr Sales Exec | E16: 08-09-2023 | F16: 25 | G16: Male | H16: Delhi | I16: 32562 | J16: 5 | K16: 77.8 | L16: Resigned | M16: Aug-24 | N16: 2 | O16: Yes
A17: EMP016 | B17: Sneha Nair | C17: Marketing | D17: Content Writer | E17: 14-07-2019 | F17: 30 | G17: Male | H17: Mumbai | I17: 33651 | J17: 2 | K17: 90.2 | L17: Active | N17: 6 | O17: Yes
A18: EMP017 | B18: Vikram Tiwari | C18: HR | D18: HR Executive | E18: 05-08-2016 | F18: 31 | G18: Male | H18: Pune | I18: 31912 | J18: 3 | K18: 79.5 | L18: Active | N18: 9 | O18: Yes
A19: EMP018 | B19: Deepak Nair | C19: IT | D19: Developer | E19: 06-04-2023 | F19: 24 | G19: Female | H19: Bangalore | I19: 44658 | J19: 5 | K19: 85 | L19: Active | N19: 2 | O19: Yes
A20: EMP019 | B20: Aakash Kumar | C20: Operations | D20: Ops Manager | E20: 24-12-2018 | F20: 29 | G20: Male | H20: Pune | I20: 39834 | J20: 5 | K20: 89.9 | L20: Active | N20: 7 | O20: Yes
A21: EMP020 | B21: Sneha Mishra | C21: IT | D21: Developer | E21: 02-06-2013 | F21: 34 | G21: Male | H21: Delhi | I21: 38821 | J21: 2 | K21: 84.9 | L21: Active | N21: 12 | O21: Yes
A22: EMP021 | B22: Suresh Kapoor | C22: IT | D22: Developer | E22: 13-04-2014 | F22: 37 | G22: Male | H22: Chennai | I22: 39964 | J22: 2 | K22: 78.6 | L22: Active | N22: 11 | O22: Yes
A23: EMP022 | B23: Nikhil Singh | C23: Finance | D23: Sr Analyst | E23: 23-11-2021 | F23: 26 | G23: Female | H23: Chennai | I23: 37147 | J23: 3 | K23: 79.2 | L23: Resigned | M23: May-24 | N23: 4 | O23: No
A24: EMP023 | B24: Ritu Chauhan | C24: IT | D24: Developer | E24: 07-09-2023 | F24: 26 | G24: Male | H24: Hyderabad | I24: 46288 | J24: 4 | K24: 75.6 | L24: Active | N24: 2 | O24: Yes
A25: EMP024 | B25: Varun Verma | C25: IT | D25: Tech Lead | E25: 26-10-2020 | F25: 28 | G25: Female | H25: Delhi | I25: 48714 | J25: 5 | K25: 72.2 | L25: Active | N25: 5 | O25: Yes
A26: EMP025 | B26: Harsh Saxena | C26: Sales | D26: Sales Manager | E26: 09-03-2016 | F26: 33 | G26: Male | H26: Delhi | I26: 32616 | J26: 2 | K26: 77.7 | L26: Active | N26: 9 | O26: Yes
A27: EMP026 | B27: Ayesha Iyer | C27: Marketing | D27: Content Writer | E27: 01-01-2020 | F27: 31 | G27: Male | H27: Delhi | I27: 31464 | J27: 3 | K27: 89.2 | L27: Active | N27: 5 | O27: No
A28: EMP027 | B28: Preeti Chauhan | C28: Sales | D28: Sales Manager | E28: 02-09-2022 | F28: 25 | G28: Female | H28: Mumbai | I28: 41674 | J28: 4 | K28: 87.7 | L28: Resigned | M28: Mar-24 | N28: 3 | O28: Yes
A29: EMP028 | B29: Ritu Joshi | C29: Marketing | D29: Marketing Exec | E29: 12-02-2014 | F29: 34 | G29: Female | H29: Delhi | I29: 38781 | J29: 5 | K29: 95.9 | L29: Active | N29: 11 | O29: Yes
A30: EMP029 | B30: Raj Gupta | C30: HR | D30: Recruiter | E30: 26-07-2019 | F30: 31 | G30: Male | H30: Mumbai | I30: 35975 | J30: 3 | K30: 79.2 | L30: Active | N30: 6 | O30: Yes
A31: EMP030 | B31: Sonal Chauhan | C31: Operations | D31: Ops Manager | E31: 08-04-2020 | F31: 31 | G31: Female | H31: Pune | I31: 27387 | J31: 3 | K31: 82.8 | L31: Active | N31: 5 | O31: Yes
A32: EMP031 | B32: Ravi Iyer | C32: IT | D32: Sr Developer | E32: 09-02-2024 | F32: 25 | G32: Female | H32: Hyderabad | I32: 40925 | J32: 2 | K32: 98 | L32: Active | N32: 1 | O32: Yes
A33: EMP032 | B33: Megha Iyer | C33: IT | D33: Tech Lead | E33: 19-07-2023 | F33: 24 | G33: Female | H33: Chennai | I33: 41114 | J33: 4 | K33: 73.2 | L33: Active | N33: 2 | O33: Yes
A34: EMP033 | B34: Ayesha Mehta | C34: Finance | D34: Finance Manager | E34: 10-12-2023 | F34: 25 | G34: Female | H34: Pune | I34: 40308 | J34: 4 | K34: 90 | L34: Active | N34: 2 | O34: Yes
A35: EMP034 | B35: Aakash Kumar | C35: Operations | D35: Team Lead | E35: 20-03-2013 | F35: 37 | G35: Male | H35: Chennai | I35: 36324 | J35: 4 | K35: 83 | L35: Active | N35: 12 | O35: Yes
A36: EMP035 | B36: Varun Singh | C36: Marketing | D36: Content Writer | E36: 15-08-2017 | F36: 32 | G36: Male | H36: Pune | I36: 37069 | J36: 3 | K36: 85.8 | L36: Active | N36: 8 | O36: Yes
A37: EMP036 | B37: Kavya Sharma | C37: Marketing | D37: Brand Manager | E37: 27-02-2019 | F37: 28 | G37: Male | H37: Hyderabad | I37: 38306 | J37: 3 | K37: 90.2 | L37: Active | N37: 6 | O37: Yes
A38: EMP037 | B38: Ritu Mehta | C38: IT | D38: Developer | E38: 21-07-2017 | F38: 30 | G38: Male | H38: Hyderabad | I38: 47431 | J38: 3 | K38: 91.4 | L38: Active | N38: 8 | O38: No
A39: EMP038 | B39: Arjun Shah | C39: HR | D39: HR Executive | E39: 15-09-2013 | F39: 38 | G39: Male | H39: Chennai | I39: 25822 | J39: 5 | K39: 78.7 | L39: Active | N39: 12 | O39: No
A40: EMP039 | B40: Manish Patel | C40: Finance | D40: Sr Analyst | E40: 17-12-2015 | F40: 34 | G40: Male | H40: Hyderabad | I40: 38991 | J40: 5 | K40: 84 | L40: Resigned | M40: Aug-24 | N40: 10 | O40: No
...

Sheet KPI_Summary
B2: HR ANALYTICS DASHBOARD — FY 2023-24
B3: Sri Guru Gobind Singh College of Commerce | B.Com (Hons.) HR Analytics Project
B5: KEY HR METRICS
B6: Total Employees | D6: Active Employees | F6: Resigned | H6: Attrition Rate | J6: Avg Salary (₹) | L6: Avg Performance
B7: =COUNTA(Employee_Data!A2:A51) -> 50 | D7: =COUNTIF(Employee_Data!L2:L51,"Active") -> 41 | F7: =COUNTIF(Employee_Data!L2:L51,"Resigned") -> 9 | H7: =COUNTIF(Employee_Data!L2:L51,"Resigned")/COUNTA(Employee_Data!A2:A51) -> 0.18 | J7: =AVERAGE(Employee_Data!I2:I51) -> 37296.2 | L7: =AVERAGE(Employee_Data!J2:J51) -> 3.52
B8: headcount | D8: employees | F8: employees | H8: rate | J8: per month | L8: out of 5
B12: DEPARTMENT-WISE BREAKDOWN
B13: Department | C13: Total | D13: Active | E13: Resigned | F13: Attrition % | G13: Avg Salary | H13: Avg Performance | I13: Avg Attendance %
B14: Finance | C14: =COUNTIF(Employee_Data!C2:C51,"Finance") -> 6 | D14: =COUNTIFS(Employee_Data!C2:C51,"Finance",Employee_Data!L2:L51,"Active") -> 2 | E14: =COUNTIFS(Employee_Data!C2:C51,"Finance",Employee_Data!L2:L51,"Resigned") -> 4 | F14: =IFERROR(D14/C14,0) -> 0.33333333 | G14: =IFERROR(AVERAGEIF(Employee_Data!C2:C51,"Finance",Employee_Data!I2:I51),0) -> 42570.167 | H14: =IFERROR(AVERAGEIF(Employee_Data!C2:C51,"Finance",Employee_Data!J2:J51),0) -> 3.3333333 | I14: =IFERROR(AVERAGEIF(Employee_Data!C2:C51,"Finance",Employee_Data!K2:K51),0) -> 87.55
B15: HR | C15: =COUNTIF(Employee_Data!C2:C51,"HR") -> 12 | D15: =COUNTIFS(Employee_Data!C2:C51,"HR",Employee_Data!L2:L51,"Active") -> 11 | E15: =COUNTIFS(Employee_Data!C2:C51,"HR",Employee_Data!L2:L51,"Resigned") -> 1 | F15: =IFERROR(D15/C15,0) -> 0.91666667 | G15: =IFERROR(AVERAGEIF(Employee_Data!C2:C51,"HR",Employee_Data!I2:I51),0) -> 31467 | H15: =IFERROR(AVERAGEIF(Employee_Data!C2:C51,"HR",Employee_Data!J2:J51),0) -> 3.6666667 | I15: =IFERROR(AVERAGEIF(Employee_Data!C2:C51,"HR",Employee_Data!K2:K51),0) -> 83.641667
B16: IT | C16: =COUNTIF(Employee_Data!C2:C51,"IT") -> 10 | D16: =COUNTIFS(Employee_Data!C2:C51,"IT",Employee_Data!L2:L51,"Active") -> 9 | E16: =COUNTIFS(Employee_Data!C2:C51,"IT",Employee_Data!L2:L51,"Resigned") -> 1 | F16: =IFERROR(D16/C16,0) -> 0.9 | G16: =IFERROR(AVERAGEIF(Employee_Data!C2:C51,"IT",Employee_Data!I2:I51),0) -> 44906.9 | H16: =IFERROR(AVERAGEIF(Employee_Data!C2:C51,"IT",Employee_Data!J2:J51),0) -> 3.5 | I16: =IFERROR(AVERAGEIF(Employee_Data!C2:C51,"IT",Employee_Data!K2:K51),0) -> 84.02
B17: Marketing | C17: =COUNTIF(Employee_Data!C2:C51,"Marketing") -> 9 | D17: =COUNTIFS(Employee_Data!C2:C51,"Marketing",Employee_Data!L2:L51,"Active") -> 8 | E17: =COUNTIFS(Employee_Data!C2:C51,"Marketing",Employee_Data!L2:L51,"Resigned") -> 1 | F17: =IFERROR(D17/C17,0) -> 0.88888889 | G17: =IFERROR(AVERAGEIF(Employee_Data!C2:C51,"Marketing",Employee_Data!I2:I51),0) -> 34326 | H17: =IFERROR(AVERAGEIF(Employee_Data!C2:C51,"Marketing",Employee_Data!J2:J51),0) -> 3.2222222 | I17: =IFERROR(AVERAGEIF(Employee_Data!C2:C51,"Marketing",Employee_Data!K2:K51),0) -> 86.144444
B18: Operations | C18: =COUNTIF(Employee_Data!C2:C51,"Operations") -> 6 | D18: =COUNTIFS(Employee_Data!C2:C51,"Operations",Employee_Data!L2:L51,"Active") -> 6 | E18: =COUNTIFS(Employee_Data!C2:C51,"Operations",Employee_Data!L2:L51,"Resigned") -> 0 | F18: =IFERROR(D18/C18,0) -> 1 | G18: =IFERROR(AVERAGEIF(Employee_Data!C2:C51,"Operations",Employee_Data!I2:I51),0) -> 33967.167 | H18: =IFERROR(AVERAGEIF(Employee_Data!C2:C51,"Operations",Employee_Data!J2:J51),0) -> 3.6666667 | I18: =IFERROR(AVERAGEIF(Employee_Data!C2:C51,"Operations",Employee_Data!K2:K51),0) -> 85.716667
B19: Sales | C19: =COUNTIF(Employee_Data!C2:C51,"Sales") -> 7 | D19: =COUNTIFS(Employee_Data!C2:C51,"Sales",Employee_Data!L2:L51,"Active") -> 5 | E19: =COUNTIFS(Employee_Data!C2:C51,"Sales",Employee_Data!L2:L51,"Resigned") -> 2 | F19: =IFERROR(D19/C19,0) -> 0.71428571 | G19: =IFERROR(AVERAGEIF(Employee_Data!C2:C51,"Sales",Employee_Data!I2:I51),0) -> 38568.429 | H19: =IFERROR(AVERAGEIF(Employee_Data!C2:C51,"Sales",Employee_Data!J2:J51),0) -> 3.7142857 | I19: =IFERROR(AVERAGEIF(Employee_Data!C2:C51,"Sales",Employee_Data!K2:K51),0) -> 81.628571
B22: GENDER & OTHER QUICK STATS
B23: Male | D23: Female | F23: Avg Age | H23: Training Done % | J23: Avg Experience
B24: =COUNTIF(Employee_Data!G2:G51,"Male") -> 34 | D24: =COUNTIF(Employee_Data!G2:G51,"Female") -> 16 | F24: =AVERAGE(Employee_Data!F2:F51) -> 30.08 | H24: =COUNTIF(Employee_Data!O2:O51,"Yes")/COUNTA(Employee_Data!O2:O51) -> 0.78 | J24: =AVERAGE(Employee_Data!N2:N51) -> 6.22
B25: employees | D25: employees | F25: years | H25: of total | J25: years

Sheet Attendance_Analysis
B2: ATTENDANCE ANALYSIS
B4: ATTENDANCE DISTRIBUTION BUCKETS
B5: Attendance Range
B6: Below 75% | D6: =COUNTIFS(Employee_Data!K2:K51,">="&0,Employee_Data!K2:K51,"<"&75) -> 3
B7: 75% – 84% | D7: =COUNTIFS(Employee_Data!K2:K51,">="&75,Employee_Data!K2:K51,"<"&85) -> 24
B8: 85% – 94% | D8: =COUNTIFS(Employee_Data!K2:K51,">="&85,Employee_Data!K2:K51,"<"&95) -> 17
B9: 95% & Above | D9: =COUNTIFS(Employee_Data!K2:K51,">="&95,Employee_Data!K2:K51,"<="&100) -> 6
B12: MONTHLY AVG ATTENDANCE TREND
B13: Apr | C13: May | D13: Jun | E13: Jul | F13: Aug | G13: Sep | H13: Oct | I13: Nov | J13: Dec | K13: Jan | L13: Feb | M13: Mar
B14: 91.2 | C14: 89.8 | D14: 87.3 | E14: 90.1 | F14: 88.5 | G14: 92.4 | H14: 91.8 | I14: 88.2 | J14: 85.9 | K14: 90.7 | L14: 93.1 | M14: 91.5
B17: DEPARTMENT AVG ATTENDANCE
B18: Department | C18: Avg Attendance % | D18: Status
B19: Finance | C19: =AVERAGEIF(Employee_Data!C2:C51,"Finance",Employee_Data!K2:K51) -> 87.55 | D19: =IF(C19>=90,"✔ Good",IF(C19>=80,"⚠ Average","✘ Concern")) -> ⚠ Average
B20: HR | C20: =AVERAGEIF(Employee_Data!C2:C51,"HR",Employee_Data!K2:K51) -> 83.641667 | D20: =IF(C20>=90,"✔ Good",IF(C20>=80,"⚠ Average","✘ Concern")) -> ⚠ Average
B21: IT | C21: =AVERAGEIF(Employee_Data!C2:C51,"IT",Employee_Data!K2:K51) -> 84.02 | D21: =IF(C21>=90,"✔ Good",IF(C21>=80,"⚠ Average","✘ Concern")) -> ⚠ Average
B22: Marketing | C22: =AVERAGEIF(Employee_Data!C2:C51,"Marketing",Employee_Data!K2:K51) -> 86.144444 | D22: =IF(C22>=90,"✔ Good",IF(C22>=80,"⚠ Average","✘ Concern")) -> ⚠ Average
B23: Operations | C23: =AVERAGEIF(Employee_Data!C2:C51,"Operations",Employee_Data!K2:K51) -> 85.716667 | D23: =IF(C23>=90,"✔ Good",IF(C23>=80,"⚠ Average","✘ Concern")) -> ⚠ Average
B24: Sales | C24: =AVERAGEIF(Employee_Data!C2:C51,"Sales",Employee_Data!K2:K51) -> 81.628571 | D24: =IF(C24>=90,"✔ Good",IF(C24>=80,"⚠ Average","✘ Concern")) -> ⚠ Average

Sheet Attrition_Analysis
B2: ATTRITION ANALYSIS
B4: Total Resigned | D4: Attrition Rate | F4: Avg Exp (Resigned) | H4: Avg Sal (Resigned)
B5: =COUNTIF(Employee_Data!L2:L51,"Resigned") -> 9 | D5: =COUNTIF(Employee_Data!L2:L51,"Resigned")/COUNTA(Employee_Data!A2:A51) -> 0.18 | F5: =AVERAGEIF(Employee_Data!L2:L51,"Resigned",Employee_Data!N2:N51) -> 4.8888889 | H5: =AVERAGEIF(Employee_Data!L2:L51,"Resigned",Employee_Data!I2:I51) -> 39192.444
B8: ATTRITION BY DEPARTMENT
B9: Department | C9: Total | D9: Resigned | E9: Attrition % | F9: Avg Salary | G9: Risk Flag
B10: Finance | C10: =COUNTIF(Employee_Data!C2:C51,"Finance") -> 6 | D10: =COUNTIFS(Employee_Data!C2:C51,"Finance",Employee_Data!L2:L51,"Resigned") -> 4 | E10: =IFERROR(D10/C10,0) -> 0.66666667 | F10: =IFERROR(AVERAGEIF(Employee_Data!C2:C51,"Finance",Employee_Data!I2:I51),0) -> 42570.167 | G10: =IF(E10>0.3,"🔴 High",IF(E10>0.15,"🟡 Medium","🟢 Low")) -> 🔴 High
B11: HR | C11: =COUNTIF(Employee_Data!C2:C51,"HR") -> 12 | D11: =COUNTIFS(Employee_Data!C2:C51,"HR",Employee_Data!L2:L51,"Resigned") -> 1 | E11: =IFERROR(D11/C11,0) -> 0.083333333 | F11: =IFERROR(AVERAGEIF(Employee_Data!C2:C51,"HR",Employee_Data!I2:I51),0) -> 31467 | G11: =IF(E11>0.3,"🔴 High",IF(E11>0.15,"🟡 Medium","🟢 Low")) -> 🟢 Low
B12: IT | C12: =COUNTIF(Employee_Data!C2:C51,"IT") -> 10 | D12: =COUNTIFS(Employee_Data!C2:C51,"IT",Employee_Data!L2:L51,"Resigned") -> 1 | E12: =IFERROR(D12/C12,0) -> 0.1 | F12: =IFERROR(AVERAGEIF(Employee_Data!C2:C51,"IT",Employee_Data!I2:I51),0) -> 44906.9 | G12: =IF(E12>0.3,"🔴 High",IF(E12>0.15,"🟡 Medium","🟢 Low")) -> 🟢 Low
B13: Marketing | C13: =COUNTIF(Employee_Data!C2:C51,"Marketing") -> 9 | D13: =COUNTIFS(Employee_Data!C2:C51,"Marketing",Employee_Data!L2:L51,"Resigned") -> 1 | E13: =IFERROR(D13/C13,0) -> 0.11111111 | F13: =IFERROR(AVERAGEIF(Employee_Data!C2:C51,"Marketing",Employee_Data!I2:I51),0) -> 34326 | G13: =IF(E13>0.3,"🔴 High",IF(E13>0.15,"🟡 Medium","🟢 Low")) -> 🟢 Low
B14: Operations | C14: =COUNTIF(Employee_Data!C2:C51,"Operations") -> 6 | D14: =COUNTIFS(Employee_Data!C2:C51,"Operations",Employee_Data!L2:L51,"Resigned") -> 0 | E14: =IFERROR(D14/C14,0) -> 0 | F14: =IFERROR(AVERAGEIF(Employee_Data!C2:C51,"Operations",Employee_Data!I2:I51),0) -> 33967.167 | G14: =IF(E14>0.3,"🔴 High",IF(E14>0.15,"🟡 Medium","🟢 Low")) -> 🟢 Low
B15: Sales | C15: =COUNTIF(Employee_Data!C2:C51,"Sales") -> 7 | D15: =COUNTIFS(Employee_Data!C2:C51,"Sales",Employee_Data!L2:L51,"Resigned") -> 2 | E15: =IFERROR(D15/C15,0) -> 0.28571429 | F15: =IFERROR(AVERAGEIF(Employee_Data!C2:C51,"Sales",Employee_Data!I2:I51),0) -> 38568.429 | G15: =IF(E15>0.3,"🔴 High",IF(E15>0.15,"🟡 Medium","🟢 Low")) -> 🟡 Medium
B18: RESIGNATIONS BY MONTH
B19: Exit Month | C19: Count
B20: Jan-24 | C20: =COUNTIF(Employee_Data!M2:M51,"Jan-24") -> 2
B21: Feb-24 | C21: =COUNTIF(Employee_Data!M2:M51,"Feb-24") -> 1
B22: Mar-24 | C22: =COUNTIF(Employee_Data!M2:M51,"Mar-24") -> 1
B23: Apr-24 | C23: =COUNTIF(Employee_Data!M2:M51,"Apr-24") -> 1
B24: May-24 | C24: =COUNTIF(Employee_Data!M2:M51,"May-24") -> 1
B25: Jun-24 | C25: =COUNTIF(Employee_Data!M2:M51,"Jun-24") -> 0
B26: Jul-24 | C26: =COUNTIF(Employee_Data!M2:M51,"Jul-24") -> 0
B27: Aug-24 | C27: =COUNTIF(Employee_Data!M2:M51,"Aug-24") -> 3

Sheet Salary_Analysis
B2: SALARY ANALYSIS
B4: SALARY DISTRIBUTION
B5: Range | C5: Count | D5: % of Total
B6: Below ₹25,000 | C6: =COUNTIFS(Employee_Data!I2:I51,">="&0,Employee_Data!I2:I51,"<="&25000) -> 0 | D6: =C6/COUNTA(Employee_Data!A2:A51) -> 0
B7: ₹25K – ₹35K | C7: =COUNTIFS(Employee_Data!I2:I51,">="&25000,Employee_Data!I2:I51,"<="&35000) -> 19 | D7: =C7/COUNTA(Employee_Data!A2:A51) -> 0.38
B8: ₹35K – ₹45K | C8: =COUNTIFS(Employee_Data!I2:I51,">="&35000,Employee_Data!I2:I51,"<="&45000) -> 23 | D8: =C8/COUNTA(Employee_Data!A2:A51) -> 0.46
B9: Above ₹45,000 | C9: =COUNTIFS(Employee_Data!I2:I51,">="&45000,Employee_Data!I2:I51,"<="&99999) -> 8 | D9: =C9/COUNTA(Employee_Data!A2:A51) -> 0.16
B12: SALARY BY DEPARTMENT
B13: Department | C13: Min Salary | D13: Max Salary | E13: Avg Salary | F13: Median (approx)
B14: Finance | C14: =IFERROR(MIN(IF(Employee_Data!C2:C51="Finance",Employee_Data!I2:I51)),0) -> 0 | D14: =IFERROR(MAX(IF(Employee_Data!C2:C51="Finance",Employee_Data!I2:I51)),0) -> 0 | E14: =AVERAGEIF(Employee_Data!C2:C51,"Finance",Employee_Data!I2:I51) -> 42570.167 | F14: =IFERROR((C14+D14)/2,0) -> 0
B15: HR | C15: =IFERROR(MIN(IF(Employee_Data!C2:C51="HR",Employee_Data!I2:I51)),0) -> 0 | D15: =IFERROR(MAX(IF(Employee_Data!C2:C51="HR",Employee_Data!I2:I51)),0) -> 0 | E15: =AVERAGEIF(Employee_Data!C2:C51,"HR",Employee_Data!I2:I51) -> 31467 | F15: =IFERROR((C15+D15)/2,0) -> 0
B16: IT | C16: =IFERROR(MIN(IF(Employee_Data!C2:C51="IT",Employee_Data!I2:I51)),0) -> 0 | D16: =IFERROR(MAX(IF(Employee_Data!C2:C51="IT",Employee_Data!I2:I51)),0) -> 0 | E16: =AVERAGEIF(Employee_Data!C2:C51,"IT",Employee_Data!I2:I51) -> 44906.9 | F16: =IFERROR((C16+D16)/2,0) -> 0
B17: Marketing | C17: =IFERROR(MIN(IF(Employee_Data!C2:C51="Marketing",Employee_Data!I2:I51)),0) -> 25822 | D17: =IFERROR(MAX(IF(Employee_Data!C2:C51="Marketing",Employee_Data!I2:I51)),0) -> 51423 | E17: =AVERAGEIF(Employee_Data!C2:C51,"Marketing",Employee_Data!I2:I51) -> 34326 | F17: =IFERROR((C17+D17)/2,0) -> 38622.5
B18: Operations | C18: =IFERROR(MIN(IF(Employee_Data!C2:C51="Operations",Employee_Data!I2:I51)),0) -> 0 | D18: =IFERROR(MAX(IF(Employee_Data!C2:C51="Operations",Employee_Data!I2:I51)),0) -> 0 | E18: =AVERAGEIF(Employee_Data!C2:C51,"Operations",Employee_Data!I2:I51) -> 33967.167 | F18: =IFERROR((C18+D18)/2,0) -> 0
B19: Sales | C19: =IFERROR(MIN(IF(Employee_Data!C2:C51="Sales",Employee_Data!I2:I51)),0) -> 0 | D19: =IFERROR(MAX(IF(Employee_Data!C2:C51="Sales",Employee_Data!I2:I51)),0) -> 0 | E19: =AVERAGEIF(Employee_Data!C2:C51,"Sales",Employee_Data!I2:I51) -> 38568.429 | F19: =IFERROR((C19+D19)/2,0) -> 0
B22: OVERALL SALARY STATS
B23: Min | D23: Max | F23: Average | H23: Total Payroll (Monthly)
B24: =MIN(Employee_Data!I2:I51) -> 25822 | D24: =MAX(Employee_Data!I2:I51) -> 51423 | F24: =AVERAGE(Employee_Data!I2:I51) -> 37296.2 | H24: =SUM(Employee_Data!I2:I51) -> 1864810

Sheet Performance_Analysis
B2: PERFORMANCE ANALYSIS
B4: PERFORMANCE RATING DISTRIBUTION
B5: Rating | C5: Description | D5: Count | E5: % Share | F5: Avg Salary
B6: 5 | C6: Outstanding | D6: =COUNTIF(Employee_Data!J2:J51,5) -> 10 | E6: =D6/COUNTA(Employee_Data!A2:A51) -> 0.2 | F6: =IFERROR(AVERAGEIF(Employee_Data!J2:J51,5,Employee_Data!I2:I51),0) -> 38265.4
B7: 4 | C7: Exceeds Expectations | D7: =COUNTIF(Employee_Data!J2:J51,4) -> 16 | E7: =D7/COUNTA(Employee_Data!A2:A51) -> 0.32 | F7: =IFERROR(AVERAGEIF(Employee_Data!J2:J51,4,Employee_Data!I2:I51),0) -> 37993.125
B8: 3 | C8: Meets Expectations | D8: =COUNTIF(Employee_Data!J2:J51,3) -> 14 | E8: =D8/COUNTA(Employee_Data!A2:A51) -> 0.28 | F8: =IFERROR(AVERAGEIF(Employee_Data!J2:J51,3,Employee_Data!I2:I51),0) -> 35822.214
B9: 2 | C9: Below Expectations | D9: =COUNTIF(Employee_Data!J2:J51,2) -> 10 | E9: =D9/COUNTA(Employee_Data!A2:A51) -> 0.2 | F9: =IFERROR(AVERAGEIF(Employee_Data!J2:J51,2,Employee_Data!I2:I51),0) -> 37275.5
B10: 1 | C10: Unsatisfactory | D10: =COUNTIF(Employee_Data!J2:J51,1) -> 0 | E10: =D10/COUNTA(Employee_Data!A2:A51) -> 0 | F10: =IFERROR(AVERAGEIF(Employee_Data!J2:J51,1,Employee_Data!I2:I51),0) -> 0
B14: PERFORMANCE vs ATTRITION
B15: Rating | C15: Total | D15: Resigned | E15: Attrition %
B16: 5 | C16: =COUNTIF(Employee_Data!J2:J51,5) -> 10 | D16: =COUNTIFS(Employee_Data!J2:J51,5,Employee_Data!L2:L51,"Resigned") -> 2 | E16: =IFERROR(D16/C16,0) -> 0.2
B17: 4 | C17: =COUNTIF(Employee_Data!J2:J51,4) -> 16 | D17: =COUNTIFS(Employee_Data!J2:J51,4,Employee_Data!L2:L51,"Resigned") -> 2 | E17: =IFERROR(D17/C17,0) -> 0.125
B18: 3 | C18: =COUNTIF(Employee_Data!J2:J51,3) -> 14 | D18: =COUNTIFS(Employee_Data!J2:J51,3,Employee_Data!L2:L51,"Resigned") -> 4 | E18: =IFERROR(D18/C18,0) -> 0.28571429
B19: 2 | C19: =COUNTIF(Employee_Data!J2:J51,2) -> 10 | D19: =COUNTIFS(Employee_Data!J2:J51,2,Employee_Data!L2:L51,"Resigned") -> 1 | E19: =IFERROR(D19/C19,0) -> 0.1
B20: 1 | C20: =COUNTIF(Employee_Data!J2:J51,1) -> 0 | D20: =COUNTIFS(Employee_Data!J2:J51,1,Employee_Data!L2:L51,"Resigned") -> 0 | E20: =IFERROR(D20/C20,0) -> 0
B24: DEPT AVG PERFORMANCE
B25: Department | C25: Avg Rating | D25: Grade
B26: Finance | C26: =IFERROR(AVERAGEIF(Employee_Data!C2:C51,"Finance",Employee_Data!J2:J51),0) -> 3.3333333 | D26: =IF(C26>=4.5,"A+",IF(C26>=4,"A",IF(C26>=3.5,"B+",IF(C26>=3,"B","C")))) -> B
B27: HR | C27: =IFERROR(AVERAGEIF(Employee_Data!C2:C51,"HR",Employee_Data!J2:J51),0) -> 3.6666667 | D27: =IF(C27>=4.5,"A+",IF(C27>=4,"A",IF(C27>=3.5,"B+",IF(C27>=3,"B","C")))) -> B+
B28: IT | C28: =IFERROR(AVERAGEIF(Employee_Data!C2:C51,"IT",Employee_Data!J2:J51),0) -> 3.5 | D28: =IF(C28>=4.5,"A+",IF(C28>=4,"A",IF(C28>=3.5,"B+",IF(C28>=3,"B","C")))) -> B+
B29: Marketing | C29: =IFERROR(AVERAGEIF(Employee_Data!C2:C51,"Marketing",Employee_Data!J2:J51),0) -> 3.2222222 | D29: =IF(C29>=4.5,"A+",IF(C29>=4,"A",IF(C29>=3.5,"B+",IF(C29>=3,"B","C")))) -> B
B30: Operations | C30: =IFERROR(AVERAGEIF(Employee_Data!C2:C51,"Operations",Employee_Data!J2:J51),0) -> 3.6666667 | D30: =IF(C30>=4.5,"A+",IF(C30>=4,"A",IF(C30>=3.5,"B+",IF(C30>=3,"B","C")))) -> B+
B31: Sales | C31: =IFERROR(AVERAGEIF(Employee_Data!C2:C51,"Sales",Employee_Data!J2:J51),0) -> 3.7142857 | D31: =IF(C31>=4.5,"A+",IF(C31>=4,"A",IF(C31>=3.5,"B+",IF(C31>=3,"B","C")))) -> B+

Sheet Charts_Dashboard
A1: VISUAL DASHBOARD — HR ANALYTICS FY 2023-24

Sheet Observations_Notes
B2: HR OBSERVATIONS & ANALYST NOTES
C4: Observation | D4: HR Action
B5: 🔴 ATTRITION | C5: Overall attrition rate is around 22%, which is slightly above the ideal 15-20% benchmark for mid-size companies. This needs attention. | D5: Recommend exit interview analysis
B6: 🟡 SALARY | C6: IT department has the highest average salary (~₹42,000/month). Sales and HR departments are on the lower end. Salary disparity may be contributing to Sales attrition. | D6: Review compensation bands for Sales
B7: 🟢 PERFORMANCE | C7: About 60% of employees are rated 3 or 4 out of 5 — Meets or Exceeds Expectations. Only ~8-10% are rated 5 (Outstanding), which is realistic for most organizations. | D7: Identify top performers for retention
B8: 🟡 ATTENDANCE | C8: Average attendance is around 89%. Two departments dipped below 85% in Dec-Jan — could be seasonal (holidays + winter absenteeism). Worth monitoring. | D8: Flag low-attendance employees
B9: 🔴 TRAINING | C9: Around 28-30% of employees have NOT completed any training in the year. This is concerning especially for Operations and Sales teams. | D9: Link training completion to appraisal
B10: 🟢 GENDER | C10: Gender split is roughly 60:40 Male:Female which is slightly better than industry average for most sectors. No red flags here. | D10: Continue inclusive hiring
B11: 🟡 EXPERIENCE | C11: Average experience is ~5-6 years. Employees with less than 2 years experience show higher resignation probability — onboarding and early engagement needs work. | D11: Strengthen 90-day onboarding
B12: 🔴 RISK | C12: Sales dept shows both high attrition AND low avg salary compared to other departments. This is a double-risk area that needs urgent HR intervention. | D12: Priority HR action needed — Sales dept
B15: LIMITATIONS & HONEST NOTES (Student Project)
B16: • Data is simulated for 50 employees — real HR data would have 500+ records
B17: • Median salary was approximated as (Min+Max)/2 since Excel MEDIAN across filtered data requires array formulas
B18: • Monthly attendance trend uses manually entered average values — ideally this would come from attendance system export
B19: • Attrition analysis doesn't account for voluntary vs involuntary exits — exit reason data was not available
B20: • Performance ratings are self-reported from managers — may have rater bias
B21: • No time-series comparison available (only one year of data collected)
